<?xml version="1.0" ?>
<sdf version="1.10">
    <world name="self_balancing_world">

        <physics name="1ms" type="ignored">
            <max_step_size>0.001</max_step_size>
            <real_time_factor>1.0</real_time_factor>
        </physics>

        <plugin
            filename="gz-sim-physics-system"
            name="gz::sim::systems::Physics">
        </plugin>
        <plugin
            filename="gz-sim-user-commands-system"
            name="gz::sim::systems::UserCommands">
        </plugin>
        <plugin
            filename="gz-sim-scene-broadcaster-system"
            name="gz::sim::systems::SceneBroadcaster">
        </plugin>
        <plugin filename="gz-sim-imu-system"
            name="gz::sim::systems::Imu">
        </plugin>

        <!-- Banish the GUI
        <gui fullscreen="0">
                <plugin filename="MinimalScene" name="3D View">
                    <gz-gui>
                        <title>3D View</title>
                        <property type="bool" key="showTitleBar">false</property>
                        <property type="string" key="state">docked</property>
                    </gz-gui>

                    <engine>ogre2</engine>
                    <scene>scene</scene>
                    <ambient_light>0.4 0.4 0.4</ambient_light>
                    <background_color>0.8 0.8 0.8</background_color>
                    <camera_pose>-6 0 6 0 0.5 0</camera_pose>
                    <camera_clip>
                        <near>0.25</near>
                        <far>25000</far>
                    </camera_clip>
                </plugin>
                <plugin filename="GzSceneManager" name="Scene Manager">
                    <gz-gui>
                        <property key="resizable" type="bool">false</property>
                        <property key="width" type="double">5</property>
                        <property key="height" type="double">5</property>
                        <property key="state" type="string">floating</property>
                        <property key="showTitleBar" type="bool">false</property>
                    </gz-gui>
                </plugin>
                <plugin filename="WorldControl" name="World control">
                    <gz-gui>
                        <title>World control</title>
                        <property type="bool" key="showTitleBar">false</property>
                        <property type="bool" key="resizable">false</property>
                        <property type="double" key="height">72</property>
                        <property type="double" key="width">121</property>
                        <property type="double" key="z">1</property>

                        <property type="string" key="state">floating</property>
                        <anchors target="3D View">
                        <line own="left" target="left"/>
                        <line own="bottom" target="bottom"/>
                        </anchors>
                    </gz-gui>

                    <play_pause>true</play_pause>
                    <step>true</step>
                    <start_paused>true</start_paused>
                    <service>/world/world_demo/control</service>
                    <stats_topic>/world/world_demo/stats</stats_topic>
                </plugin>
                <plugin filename="WorldStats" name="World stats">
                    <gz-gui>
                        <title>World stats</title>
                        <property type="bool" key="showTitleBar">false</property>
                        <property type="bool" key="resizable">false</property>
                        <property type="double" key="height">110</property>
                        <property type="double" key="width">290</property>
                        <property type="double" key="z">1</property>

                        <property type="string" key="state">floating</property>
                        <anchors target="3D View">
                        <line own="right" target="right"/>
                        <line own="bottom" target="bottom"/>
                        </anchors>
                    </gz-gui>

                    <sim_time>true</sim_time>
                    <real_time>true</real_time>
                    <real_time_factor>true</real_time_factor>
                    <iterations>true</iterations>
                    <topic>/world/world_demo/stats</topic>

                </plugin>
                <plugin filename="EntityTree" name="Entity tree">
                </plugin>
        </gui>-->

        <light type="directional" name="sun">
            <cast_shadows>true</cast_shadows>
            <pose>0 0 10 0 0 0</pose>
            <diffuse>0.8 0.8 0.8 1</diffuse>
            <specular>0.2 0.2 0.2 1</specular>
            <attenuation>
                <range>1000</range>
                <constant>0.9</constant>
                <linear>0.01</linear>
                <quadratic>0.001</quadratic>
            </attenuation>
            <direction>-0.5 0.1 -0.9</direction>
        </light>

        <model name="ground_plane">
            <static>true</static>
            <link name="link">
                <collision name="collision">
                    <geometry>
                        <plane>
                            <normal>0 0 1</normal>
                        </plane>
                    </geometry>
                </collision>
                <visual name="visual">
                    <geometry>
                        <plane>
                            <normal>0 0 1</normal>
                        <size>100 100</size>
                        </plane>
                    </geometry>
                    <material>
                        <ambient>0.8 0.8 0.8 1</ambient>
                        <diffuse>0.8 0.8 0.8 1</diffuse>
                        <specular>0.8 0.8 0.8 1</specular>
                    </material>
                </visual>
            </link>
        </model>
        
        <model name='self_Balancer' canonical_link='boxBody'>
            <pose relative_to='world'>0 0 0 0 0 0</pose>
            <link name='boxBody'>
                <pose relative_to='__model__'>0 0 1 0 0 0</pose>
                <inertial>
                    <mass>.1</mass>
                    <inertia>
                        <ixx>0.001333</ixx>
                        <ixy>0</ixy>
                        <ixz>0</ixz>
                        <iyy>0.00075</iyy>
                        <iyz>0</iyz>
                        <izz>0.002083</izz>
                    </inertia>
                </inertial>

                <visual name='visual'>
                    <geometry>
                        <box>
                            <size>0.4 0.3 0.6</size>
                        </box>
                    </geometry>
                    <material>
                        <ambient>0.0 0.0 1.0 1</ambient>
                        <diffuse>0.0 0.0 1.0 1</diffuse>
                        <specular>0.0 0.0 1.0 1</specular>
                    </material>
                </visual>

                <collision name='collision'>
                    <geometry>
                        <box>
                            <size>0.4 0.3 0.6</size>
                        </box>
                    </geometry>
                </collision>

                <sensor name="imu_sensor" type="imu">
                    <always_on>1</always_on>
                    <update_rate>20</update_rate>
                    <visualize>true</visualize>
                    <topic>imu</topic>
                </sensor>
            </link>

            <link name='left_wheel'>
                <pose relative_to="boxBody">-0.25 0 -0.25 0 1.570796 0</pose>
                <inertial>
                    <mass>.05</mass>
                    <inertia>
                        <ixx>0.000562</ixx>
                        <ixy>0</ixy>
                        <ixz>0</ixz>
                        <iyy>0.000323</iyy>
                        <iyz>0</iyz>
                        <izz>0.000323</izz>
                    </inertia>
                </inertial>

                <visual name='visual'>
                    <geometry>
                        <cylinder>
                            <radius>0.15</radius>
                            <length>0.1</length>
                        </cylinder>
                    </geometry>
                    <material>
                        <ambient>1.0 0.0 0.0 1</ambient>
                        <diffuse>1.0 0.0 0.0 1</diffuse>
                        <specular>1.0 0.0 0.0 1</specular>
                    </material>
                </visual>

                <collision name='collision'>
                    <geometry>
                        <cylinder>
                            <radius>0.15</radius>
                            <length>0.1</length>
                        </cylinder>
                    </geometry>
                </collision>
            </link>

            <link name='right_wheel'>
                <pose relative_to="boxBody">0.25 0 -.25 0 1.570796 0</pose> 
                <inertial>
                    <mass>.05</mass>
                    <inertia>
                        <ixx>0.000562</ixx>
                        <ixy>0</ixy>
                        <ixz>0</ixz>
                        <iyy>0.000323</iyy>
                        <iyz>0</iyz>
                        <izz>0.000323</izz>
                    </inertia>
                </inertial>

                <visual name='visual'>
                    <geometry>
                        <cylinder>
                            <radius>0.15</radius>
                            <length>0.1</length>
                        </cylinder>
                    </geometry>
                    <material>
                        <ambient>1.0 0.0 0.0 1</ambient>
                        <diffuse>1.0 0.0 0.0 1</diffuse>
                        <specular>1.0 0.0 0.0 1</specular>
                    </material>
                </visual>

                <collision name='collision'>
                    <geometry>
                        <cylinder>
                            <radius>0.15</radius>
                            <length>0.1</length>
                        </cylinder>
                    </geometry>
                </collision>
            </link>

            <joint name='leftJoint' type='revolute'>
                <pose relative_to='left_wheel'/>
                <parent>boxBody</parent>
                <child>left_wheel</child>
                <axis>
                    <xyz expressed_in='__model__'>1 0 0</xyz> 
                    <limit>
                        <lower>-1.79769e+308</lower>    <!--negative infinity-->
                        <upper>1.79769e+308</upper>     <!--positive infinity-->
                    </limit>
                </axis>
            </joint>

            <joint name='rightJoint' type='revolute'>
                <pose relative_to='right_wheel'/>
                <parent>boxBody</parent>
                <child>right_wheel</child>
                <axis>
                    <xyz expressed_in='__model__'>1 0 0</xyz> 
                    <limit>
                        <lower>-1.79769e+308</lower>    <!--negative infinity-->
                        <upper>1.79769e+308</upper>     <!--positive infinity-->
                    </limit>
                </axis>
            </joint>
            
            <!--diff drive plugin-->
            <plugin
                filename="gz-sim-diff-drive-system"
                name="gz::sim::systems::DiffDrive">
                <left_joint>leftJoint</left_joint>
                <right_joint>rightJoint</right_joint>
                <wheel_separation>.5</wheel_separation>
                <wheel_radius>0.15</wheel_radius>
                <odom_publish_frequency>20</odom_publish_frequency>
                <topic>balanceVel</topic>
            </plugin>
        </model>
    </world>
</sdf>
