<?xml version="1.0" ?>
<sdf version="1.10">
    <world name="self_balancing_world">

        <physics name="1ms" type="ignored">
            <max_step_size>0.001</max_step_size>
            <real_time_factor>1.0</real_time_factor>
        </physics>

        <plugin
            filename="gz-sim-physics-system"
            name="gz::sim::systems::Physics">
        </plugin>
        <plugin
            filename="gz-sim-user-commands-system"
            name="gz::sim::systems::UserCommands">
        </plugin>
        <plugin
            filename="gz-sim-scene-broadcaster-system"
            name="gz::sim::systems::SceneBroadcaster">
        </plugin>
        <!--IMU Plugin here, maybe also ROS? I'm just making the body rn-->

        <light type="directional" name="sun">
            <cast_shadows>true</cast_shadows>
            <pose>0 0 10 0 0 0</pose>
            <diffuse>0.8 0.8 0.8 1</diffuse>
            <specular>0.2 0.2 0.2 1</specular>
            <attenuation>
                <range>1000</range>
                <constant>0.9</constant>
                <linear>0.01</linear>
                <quadratic>0.001</quadratic>
            </attenuation>
            <direction>-0.5 0.1 -0.9</direction>
        </light>

        <model name="ground_plane">
            <static>true</static>
            <link name="link">
                <collision name="collision">
                    <geometry>
                        <plane>
                            <normal>0 0 1</normal>
                        </plane>
                    </geometry>
                </collision>
                <visual name="visual">
                    <geometry>
                        <plane>
                            <normal>0 0 1</normal>
                        <size>100 100</size>
                        </plane>
                    </geometry>
                    <material>
                        <ambient>0.8 0.8 0.8 1</ambient>
                        <diffuse>0.8 0.8 0.8 1</diffuse>
                        <specular>0.8 0.8 0.8 1</specular>
                    </material>
                </visual>
            </link>
        </model>
        
        <model name='self_Balancer' canonical_link='boxBody'>
            <pose relative_to='world'>0 0 0 0 0 0</pose>
            <link name='boxBody'>
                <pose relative_to='__model__'>0 0 1 0 0 0</pose>
                <inertial>
                    <mass>.1</mass>
                    <inertia>
                        <ixx>0.001333</ixx>
                        <ixy>0</ixy>
                        <ixz>0</ixz>
                        <iyy>0.00075</iyy>
                        <iyz>0</iyz>
                        <izz>0.002083</izz>
                    </inertia>
                </inertial>

                <visual name='visual'>
                    <geometry>
                        <box>
                            <size>0.4 0.3 0.6</size>
                        </box>
                    </geometry>
                    <material>
                        <ambient>0.0 0.0 1.0 1</ambient>
                        <diffuse>0.0 0.0 1.0 1</diffuse>
                        <specular>0.0 0.0 1.0 1</specular>
                    </material>
                </visual>

                <collision name='collision'>
                    <geometry>
                        <box>
                            <size>0.4 0.3 0.6</size>
                        </box>
                    </geometry>
                </collision>
            </link>

            <link name='left_wheel'>
                <pose relative_to="boxBody">-0.25 0 -0.25 0 1.570796 0</pose>
                <inertial>
                    <mass>.05</mass>
                    <inertia>
                        <ixx>0.000562</ixx>
                        <ixy>0</ixy>
                        <ixz>0</ixz>
                        <iyy>0.000323</iyy>
                        <iyz>0</iyz>
                        <izz>0.000323</izz>
                    </inertia>
                </inertial>

                <visual name='visual'>
                    <geometry>
                        <cylinder>
                            <radius>0.15</radius>
                            <length>0.1</length>
                        </cylinder>
                    </geometry>
                    <material>
                        <ambient>1.0 0.0 0.0 1</ambient>
                        <diffuse>1.0 0.0 0.0 1</diffuse>
                        <specular>1.0 0.0 0.0 1</specular>
                    </material>
                </visual>

                <collision name='collision'>
                    <geometry>
                        <cylinder>
                            <radius>0.15</radius>
                            <length>0.1</length>
                        </cylinder>
                    </geometry>
                </collision>
            </link>

            <link name='right_wheel'>
                <pose relative_to="boxBody">0.25 0 -.25 0 1.570796 0</pose> 
                <inertial>
                    <mass>.05</mass>
                    <inertia>
                        <ixx>0.000562</ixx>
                        <ixy>0</ixy>
                        <ixz>0</ixz>
                        <iyy>0.000323</iyy>
                        <iyz>0</iyz>
                        <izz>0.000323</izz>
                    </inertia>
                </inertial>

                <visual name='visual'>
                    <geometry>
                        <cylinder>
                            <radius>0.15</radius>
                            <length>0.1</length>
                        </cylinder>
                    </geometry>
                    <material>
                        <ambient>1.0 0.0 0.0 1</ambient>
                        <diffuse>1.0 0.0 0.0 1</diffuse>
                        <specular>1.0 0.0 0.0 1</specular>
                    </material>
                </visual>

                <collision name='collision'>
                    <geometry>
                        <cylinder>
                            <radius>0.15</radius>
                            <length>0.1</length>
                        </cylinder>
                    </geometry>
                </collision>
            </link>

            <joint name='leftJoint' type='revolute'>
                <pose relative_to='left_wheel'/>
                <parent>boxBody</parent>
                <child>left_wheel</child>
                <axis>
                    <xyz expressed_in='__model__'>1 0 0</xyz> 
                    <limit>
                        <lower>-1.79769e+308</lower>    <!--negative infinity-->
                        <upper>1.79769e+308</upper>     <!--positive infinity-->
                    </limit>
                </axis>
            </joint>

            <joint name='rightJoint' type='revolute'>
                <pose relative_to='right_wheel'/>
                <parent>boxBody</parent>
                <child>right_wheel</child>
                <axis>
                    <xyz expressed_in='__model__'>1 0 0</xyz> 
                    <limit>
                        <lower>-1.79769e+308</lower>    <!--negative infinity-->
                        <upper>1.79769e+308</upper>     <!--positive infinity-->
                    </limit>
                </axis>
            </joint>
        </model>
    </world>
</sdf>